SettingsMode: WriteDisable

Tree: false
Frequency: 1
Rarity: 2.5
RotateRandomly: true
SpawnHeight: randomY
MinHeight: 100
MaxHeight: 250

Block(3,1,-3,STONE)
Block(3,2,-3,STONE)
Block(3,3,-3,STONE)
Block(1,2,-4,STONE)
Block(1,1,-4,STONE)
Block(2,2,1,STONE)
Block(2,1,1,STONE)
Block(2,3,1,STONE)
Block(1,2,3,DIRT)
Block(-1,1,0,STONE)
Block(-1,2,0,STONE)
Block(3,1,-2,STONE)
Block(0,1,-1,STONE)
Block(3,2,-2,STONE)
Block(0,0,-1,STONE)
Block(3,3,-2,STONE)
Block(0,3,-1,STONE)
Block(3,4,-2,DIRT)
Block(0,2,-1,STONE)
Block(3,0,0,STONE)
Block(1,1,-3,STONE)
Block(1,2,-3,STONE)
Block(3,4,0,DIRT)
Block(3,3,0,STONE)
Block(3,2,0,STONE)
Block(-3,2,3,STONE)
Block(3,1,0,STONE)
Block(-3,1,3,STONE)
Block(-1,2,-2,STONE)
Block(-1,1,-2,STONE)
Block(2,1,2,STONE)
Block(2,2,2,STONE)
Block(0,1,0,STONE)
Block(0,0,0,STONE)
Block(0,3,0,STONE)
Block(0,2,0,STONE)
Block(-4,1,4,STONE)
Block(1,2,-2,STONE)
Block(1,3,-2,STONE)
Block(1,0,-2,STONE)
Block(1,1,-2,STONE)
Block(3,3,1,STONE)
Block(3,2,1,STONE)
Block(3,1,1,STONE)
Block(2,1,-1,STONE)
Block(2,0,-1,STONE)
Block(4,4,0,DIRT)
Block(2,4,-1,DIRT)
Block(2,3,-1,STONE)
Block(2,2,-1,STONE)
Block(-1,1,2,STONE)
Block(-4,1,3,STONE)
Block(4,1,0,STONE)
Block(4,0,0,STONE)
Block(3,2,-4,STONE)
Block(4,3,0,STONE)
Block(4,2,0,STONE)
Block(-4,2,3,STONE)
Block(4,2,-4,STONE)
Block(1,3,-1,STONE)
Block(1,1,-1,STONE)
Block(1,2,-1,STONE)
Block(3,2,2,STONE)
Block(1,0,-1,STONE)
Block(3,1,2,STONE)
Block(2,0,-2,STONE)
Block(4,4,1,DIRT)
Block(4,3,1,STONE)
Block(2,3,-2,STONE)
Block(2,2,-2,STONE)
Block(2,1,-2,STONE)
Block(-1,2,1,STONE)
Block(-1,1,1,STONE)
Block(0,2,-4,STONE)
Block(0,1,-4,STONE)
Block(0,1,2,STONE)
Block(0,2,2,STONE)
Block(4,2,1,STONE)
Block(4,1,1,STONE)
Block(4,3,-3,STONE)
Block(4,2,-3,STONE)
Block(4,1,-3,STONE)
Block(-2,1,2,STONE)
Block(4,3,2,STONE)
Block(4,2,2,STONE)
Block(2,3,-3,STONE)
Block(2,2,-3,STONE)
Block(2,1,-3,STONE)
Block(0,2,1,STONE)
Block(0,1,1,STONE)
Block(4,1,2,STONE)
Block(4,4,-2,DIRT)
Block(4,3,-2,STONE)
Block(4,2,-2,STONE)
Block(4,1,-2,STONE)
Block(-1,1,3,STONE)
Block(4,2,3,STONE)
Block(2,2,-4,STONE)
Block(1,3,0,STONE)
Block(1,2,0,STONE)
Block(1,1,0,STONE)
Block(1,0,0,STONE)
Block(0,3,-2,STONE)
Block(3,0,-1,STONE)
Block(3,1,-1,STONE)
Block(3,2,-1,STONE)
Block(0,0,-2,STONE)
Block(3,3,-1,STONE)
Block(3,4,-1,DIRT)
Block(0,2,-2,STONE)
Block(0,1,-2,STONE)
Block(4,5,-1,DIRT)
Block(4,4,-1,DIRT)
Block(4,1,-1,STONE)
Block(4,0,-1,STONE)
Block(4,3,-1,STONE)
Block(4,2,-1,STONE)
Block(-1,2,-1,STONE)
Block(-1,1,-1,STONE)
Block(1,2,1,STONE)
Block(1,1,1,STONE)
Block(0,2,-3,STONE)
Block(0,1,-3,STONE)
Block(2,3,0,STONE)
Block(2,2,0,STONE)
Block(-2,2,3,STONE)
Block(2,1,0,STONE)
Block(-2,1,3,STONE)
Block(2,0,0,STONE)
Block(1,2,2,STONE)
Block(1,1,2,STONE)
