SettingsMode: WriteDisable

Tree: false
Frequency: 1
Rarity: 2.5
RotateRandomly: true
SpawnHeight: randomY
MinHeight: 100
MaxHeight: 250

Block(3,1,-3,STONE)
Block(3,2,-3,STONE)
Block(3,3,-3,STONE)
Block(6,3,1,GRASS)
Block(3,4,-3,GRASS)
Block(1,4,-4,GRASS)
Block(2,4,2,GRASS)
Block(1,2,-4,STONE)
Block(1,3,-4,STONE)
Block(-1,4,-3,GRASS)
Block(-1,3,-3,STONE)
Block(-1,2,-3,STONE)
Block(3,5,0,GRASS)
Block(-1,1,-3,STONE)
Block(2,2,1,STONE)
Block(2,1,1,STONE)
Block(2,4,1,STONE)
Block(2,3,1,STONE)
Block(5,3,-3,GRASS)
Block(-1,3,0,GRASS)
Block(0,4,-1,GRASS)
Block(3,1,-2,STONE)
Block(3,2,-2,STONE)
Block(3,3,-2,STONE)
Block(0,3,-1,STONE)
Block(3,4,-2,GRASS)
Block(0,2,-1,STONE)
Block(1,3,-3,STONE)
Block(1,4,-3,GRASS)
Block(1,1,-3,STONE)
Block(1,2,-3,STONE)
Block(3,4,0,STONE)
Block(3,3,0,STONE)
Block(3,2,0,STONE)
Block(3,1,0,STONE)
Block(-1,4,-2,GRASS)
Block(3,5,1,GRASS)
Block(-1,3,-2,STONE)
Block(3,4,1,STONE)
Block(-1,2,-2,STONE)
Block(2,3,2,STONE)
Block(2,2,2,STONE)
Block(0,3,0,STONE)
Block(0,2,0,STONE)
Block(0,4,0,GRASS)
Block(1,4,-2,GRASS)
Block(1,2,-2,STONE)
Block(1,3,-2,STONE)
Block(-2,3,-5,GRASS)
Block(1,1,-2,STONE)
Block(3,3,1,STONE)
Block(3,2,1,STONE)
Block(3,1,1,STONE)
Block(-1,3,-5,GRASS)
Block(3,4,2,GRASS)
Block(3,3,2,STONE)
Block(2,1,-1,STONE)
Block(4,5,0,GRASS)
Block(4,4,0,STONE)
Block(2,5,-1,GRASS)
Block(2,4,-1,STONE)
Block(2,3,-1,STONE)
Block(2,2,-1,STONE)
Block(4,1,0,STONE)
Block(4,0,0,STONE)
Block(4,3,0,STONE)
Block(4,2,0,STONE)
Block(3,3,-4,GRASS)
Block(1,5,-1,GRASS)
Block(1,3,-1,STONE)
Block(1,4,-1,STONE)
Block(1,1,-1,STONE)
Block(1,2,-1,STONE)
Block(4,3,-4,GRASS)
Block(3,2,2,STONE)
Block(-1,4,-4,GRASS)
Block(-1,3,-4,STONE)
Block(-1,2,-4,STONE)
Block(3,3,3,GRASS)
Block(4,4,1,STONE)
Block(4,3,1,STONE)
Block(4,5,1,GRASS)
Block(2,4,-2,GRASS)
Block(2,3,-2,STONE)
Block(2,2,-2,STONE)
Block(2,1,-2,STONE)
Block(0,2,-4,STONE)
Block(0,4,-4,GRASS)
Block(0,3,-4,STONE)
Block(4,0,1,STONE)
Block(4,2,1,STONE)
Block(4,1,1,STONE)
Block(-2,2,-3,STONE)
Block(4,3,-3,STONE)
Block(4,2,-3,STONE)
Block(4,4,-3,GRASS)
Block(-2,4,-3,GRASS)
Block(-2,3,-3,STONE)
Block(-4,3,-3,GRASS)
Block(4,3,2,STONE)
Block(4,2,2,STONE)
Block(4,4,2,GRASS)
Block(2,3,-3,STONE)
Block(2,2,-3,STONE)
Block(2,1,-3,STONE)
Block(2,4,-3,GRASS)
Block(5,4,0,GRASS)
Block(5,3,0,STONE)
Block(5,2,0,STONE)
Block(0,2,1,STONE)
Block(0,3,-5,GRASS)
Block(0,4,1,GRASS)
Block(0,3,1,STONE)
Block(4,1,2,STONE)
Block(4,4,-2,GRASS)
Block(-2,3,-4,GRASS)
Block(4,3,-2,STONE)
Block(4,2,-2,STONE)
Block(4,1,-2,STONE)
Block(4,2,3,STONE)
Block(4,3,3,GRASS)
Block(2,2,-4,STONE)
Block(-3,3,-5,GRASS)
Block(1,5,0,GRASS)
Block(1,4,0,STONE)
Block(2,3,-4,GRASS)
Block(1,3,0,STONE)
Block(1,2,0,STONE)
Block(5,4,1,GRASS)
Block(5,3,1,STONE)
Block(5,2,1,STONE)
Block(5,1,1,STONE)
Block(0,4,-2,STONE)
Block(0,3,-2,STONE)
Block(0,5,-2,GRASS)
Block(3,1,-1,STONE)
Block(3,2,-1,STONE)
Block(3,3,-1,STONE)
Block(3,4,-1,STONE)
Block(0,2,-2,STONE)
Block(3,5,-1,GRASS)
Block(0,1,-2,STONE)
Block(4,5,-1,GRASS)
Block(4,4,-1,STONE)
Block(4,1,-1,STONE)
Block(4,3,-1,STONE)
Block(4,2,-1,STONE)
Block(-1,4,-1,GRASS)
Block(-1,3,-1,STONE)
Block(5,3,-1,GRASS)
Block(5,2,-1,STONE)
Block(-3,3,-4,GRASS)
Block(1,5,1,GRASS)
Block(1,4,1,STONE)
Block(2,3,-5,GRASS)
Block(1,3,1,STONE)
Block(1,2,1,STONE)
Block(5,3,2,GRASS)
Block(0,3,-3,STONE)
Block(0,2,-3,STONE)
Block(0,5,-3,GRASS)
Block(0,4,-3,STONE)
Block(0,1,-3,STONE)
Block(1,3,-5,GRASS)
Block(2,5,1,GRASS)
Block(-2,3,-2,GRASS)
Block(2,3,0,STONE)
Block(2,2,0,STONE)
Block(2,5,0,GRASS)
Block(2,4,0,STONE)
Block(2,1,0,STONE)
Block(5,3,-2,GRASS)
Block(-3,3,-3,STONE)
Block(-3,4,-3,GRASS)
Block(1,3,2,GRASS)
