SettingsMode: WriteDisable

Tree: false
Frequency: 1
Rarity: 2.5
RotateRandomly: true
SpawnHeight: randomY
MinHeight: 100
MaxHeight: 250

Block(2,4,2,GRASS)
Block(-1,5,0,STONE)
Block(-1,4,-3,GRASS)
Block(-1,4,0,STONE)
Block(-1,3,-3,STONE)
Block(-1,6,0,GRASS)
Block(2,2,1,STONE)
Block(2,4,1,GRASS)
Block(2,3,1,STONE)
Block(-3,3,-2,STONE)
Block(-3,4,-2,GRASS)
Block(-1,1,0,STONE)
Block(-1,0,0,STONE)
Block(-1,3,0,STONE)
Block(-1,2,0,STONE)
Block(0,5,-1,STONE)
Block(0,4,-1,STONE)
Block(0,6,-1,GRASS)
Block(0,1,-1,STONE)
Block(0,3,-1,STONE)
Block(0,2,-1,STONE)
Block(1,4,-3,GRASS)
Block(3,4,0,GRASS)
Block(3,3,0,STONE)
Block(-1,5,-2,GRASS)
Block(-1,4,-2,STONE)
Block(-1,3,-2,STONE)
Block(3,4,1,GRASS)
Block(-1,2,-2,STONE)
Block(-3,3,-1,STONE)
Block(-3,4,-1,GRASS)
Block(0,1,0,STONE)
Block(0,0,0,STONE)
Block(0,3,0,STONE)
Block(0,2,0,STONE)
Block(0,5,0,STONE)
Block(0,4,0,STONE)
Block(0,6,0,GRASS)
Block(1,4,-2,GRASS)
Block(1,3,-2,STONE)
Block(-1,4,2,GRASS)
Block(-4,4,-1,GRASS)
Block(-2,5,0,GRASS)
Block(-2,4,0,STONE)
Block(-2,3,0,STONE)
Block(-2,2,0,STONE)
Block(-2,1,0,STONE)
Block(4,4,0,GRASS)
Block(2,4,-1,GRASS)
Block(2,3,-1,STONE)
Block(1,5,-1,GRASS)
Block(1,3,-1,STONE)
Block(1,4,-1,STONE)
Block(1,2,-1,STONE)
Block(-1,4,-4,GRASS)
Block(-1,4,1,STONE)
Block(-1,3,1,STONE)
Block(-1,5,1,GRASS)
Block(-1,2,1,STONE)
Block(-1,1,1,STONE)
Block(0,1,2,STONE)
Block(0,4,-4,GRASS)
Block(0,3,2,STONE)
Block(0,2,2,STONE)
Block(0,5,2,GRASS)
Block(0,4,2,STONE)
Block(-3,3,0,STONE)
Block(-3,2,0,STONE)
Block(-2,4,-3,GRASS)
Block(-3,5,0,GRASS)
Block(-3,4,0,STONE)
Block(-4,4,-3,GRASS)
Block(0,0,1,STONE)
Block(0,2,1,STONE)
Block(0,1,1,STONE)
Block(0,4,1,STONE)
Block(0,3,1,STONE)
Block(0,5,1,GRASS)
Block(-2,4,-4,GRASS)
Block(-4,4,-2,GRASS)
Block(-2,4,1,GRASS)
Block(-2,3,1,STONE)
Block(1,6,0,GRASS)
Block(1,5,0,STONE)
Block(1,4,0,STONE)
Block(1,3,0,STONE)
Block(1,2,0,STONE)
Block(1,1,0,STONE)
Block(0,4,-2,STONE)
Block(0,3,-2,STONE)
Block(0,5,-2,GRASS)
Block(-4,4,0,GRASS)
Block(-4,3,0,STONE)
Block(0,2,-2,STONE)
Block(-2,4,-1,STONE)
Block(-2,3,-1,STONE)
Block(-2,2,-1,STONE)
Block(-2,5,-1,GRASS)
Block(-1,5,-1,DIRT)
Block(-1,4,-1,STONE)
Block(-1,3,-1,STONE)
Block(-1,2,-1,STONE)
Block(-1,1,-1,STONE)
Block(-3,4,-4,GRASS)
Block(1,5,1,GRASS)
Block(1,4,1,STONE)
Block(1,3,1,STONE)
Block(1,2,1,STONE)
Block(1,1,1,STONE)
Block(0,3,-3,STONE)
Block(0,5,-3,GRASS)
Block(0,4,-3,STONE)
Block(0,2,3,STONE)
Block(0,4,3,GRASS)
Block(0,3,3,STONE)
Block(-2,3,-2,STONE)
Block(-2,4,-2,GRASS)
Block(2,3,0,STONE)
Block(2,2,0,STONE)
Block(2,5,0,GRASS)
Block(2,4,0,STONE)
Block(-3,4,-3,GRASS)
Block(1,4,2,GRASS)
Block(1,3,2,STONE)
Block(1,2,2,STONE)
