SettingsMode: WriteDisable

Tree: false
Frequency: 1
Rarity: 2.5
RotateRandomly: true
SpawnHeight: randomY
MinHeight: 100
MaxHeight: 250

Block(-1,5,0,GRASS)
Block(-1,4,0,STONE)
Block(2,2,1,STONE)
Block(2,3,1,GRASS)
Block(-3,2,-2,GRASS)
Block(1,2,3,GRASS)
Block(-1,1,0,STONE)
Block(-1,3,0,STONE)
Block(-1,2,0,STONE)
Block(0,3,-1,GRASS)
Block(0,2,-1,STONE)
Block(3,2,0,GRASS)
Block(2,2,2,GRASS)
Block(-3,1,-1,STONE)
Block(-3,2,-1,STONE)
Block(-3,3,-1,GRASS)
Block(0,1,0,STONE)
Block(0,0,0,STONE)
Block(0,3,0,STONE)
Block(0,2,0,STONE)
Block(0,5,0,GRASS)
Block(0,4,0,STONE)
Block(-1,2,2,GRASS)
Block(-2,4,0,GRASS)
Block(-2,3,0,STONE)
Block(-2,2,0,STONE)
Block(-2,1,0,STONE)
Block(1,3,-1,GRASS)
Block(1,2,-1,STONE)
Block(-1,4,1,GRASS)
Block(-1,3,1,STONE)
Block(-1,2,1,STONE)
Block(-1,1,1,STONE)
Block(-3,1,0,STONE)
Block(0,3,2,GRASS)
Block(0,2,2,STONE)
Block(-3,3,0,STONE)
Block(-3,2,0,STONE)
Block(-3,4,0,GRASS)
Block(-2,2,2,GRASS)
Block(0,2,1,STONE)
Block(0,1,1,STONE)
Block(0,4,1,GRASS)
Block(0,3,1,STONE)
Block(-2,3,1,GRASS)
Block(-2,2,1,STONE)
Block(-2,1,1,STONE)
Block(1,5,0,GRASS)
Block(1,4,0,STONE)
Block(1,3,0,STONE)
Block(1,2,0,STONE)
Block(1,1,0,STONE)
Block(1,0,0,STONE)
Block(-4,2,0,GRASS)
Block(-2,3,-1,GRASS)
Block(-2,2,-1,STONE)
Block(-2,1,-1,STONE)
Block(-3,2,2,GRASS)
Block(-1,3,-1,GRASS)
Block(-1,2,-1,STONE)
Block(1,4,1,GRASS)
Block(1,3,1,STONE)
Block(1,2,1,STONE)
Block(1,1,1,STONE)
Block(-2,2,-2,DIRT)
Block(-3,2,1,STONE)
Block(-3,1,1,STONE)
Block(-3,3,1,GRASS)
Block(2,3,0,STONE)
Block(2,2,0,STONE)
Block(2,4,0,GRASS)
Block(2,1,0,STONE)
Block(1,3,2,GRASS)
Block(1,2,2,STONE)
